Workbook

Sheet Itemoverzicht
A1: ICF_groep | B1: ICF_subgroep | C1: ICF_itemomschrijving | D1: Schaal origineel | E1: Schaalcode | F1: SCORE | G1: Cutoff (licht) | H1: Cutoff matig | I1: Cutoff ernstig | J1: ICF score_totaal
A2: II. Functies/anatomisch | B2: 05. Lichaam/regulatie | C2: Kortademig zonder inspanning | D2: SQ48 | E2: SQ48_SOMAT_1 | F2: #N/A | G2: 2 | H2: 3 | I2: 4 | J2: =IF(F2>=I2,4,IF(F2>=H2,3,IF(F2>=G2,2,1))) -> #N/A
A3: II. Functies/anatomisch | B3: 06. Activatie/sensorimotorisch | C3: Vertraagd of langzaam voelen | D3: SQ48 | E3: SQ48_COGN_2 | F3: #N/A | G3: 2 | H3: 3 | I3: 4 | J3: =IF(F3>=I3,4,IF(F3>=H3,3,IF(F3>=G3,2,1))) -> #N/A
A4: II. Functies/anatomisch | B4: 02. Stemming/positief affect | C4: Ontevreden zijn | D4: SQ48 | E4: SQ48_DEPR_3 | F4: #N/A | G4: 2 | H4: 3 | I4: 4 | J4: =IF(F4>=I4,4,IF(F4>=H4,3,IF(F4>=G4,2,1))) -> #N/A
A5: III. Activiteiten | B5: 01. Stress/negatief affect | C5: Angstig in menigte zijn | D5: SQ48 | E5: SQ48_AGORA_4 | F5: #N/A | G5: 2 | H5: 3 | I5: 4 | J5: =IF(F5>=I5,4,IF(F5>=H5,3,IF(F5>=G5,2,1))) -> #N/A
A6: II. Functies/anatomisch | B6: 05. Lichaam/regulatie | C6: Hartkloppingen | D6: SQ48 | E6: SQ48_SOMAT_5 | F6: #N/A | G6: 2 | H6: 3 | I6: 4 | J6: =IF(F6>=I6,4,IF(F6>=H6,3,IF(F6>=G6,2,1))) -> #N/A
A7: IV. Participatie | B7: 02. Stemming/positief affect | C7: Moeite met beslissingen | D7: SQ48 | E7: SQ48_COGN_6 | F7: #N/A | G7: 2 | H7: 3 | I7: 4 | J7: =IF(F7>=I7,4,IF(F7>=H7,3,IF(F7>=G7,2,1))) -> #N/A
A8: III. Activiteiten | B8: 02. Stemming/positief affect | C8: Niet kunnen genieten | D8: SQ48 | E8: SQ48_DEPR_7 | F8: #N/A | G8: 2 | H8: 3 | I8: 4 | J8: =IF(F8>=I8,4,IF(F8>=H8,3,IF(F8>=G8,2,1))) -> #N/A
A9: IV. Participatie | B9: 01. Stress/negatief affect | C9: Moeite met open ruimtes | D9: SQ48 | E9: SQ48_AGORA_8 | F9: #N/A | G9: 2 | H9: 3 | I9: 4 | J9: =IF(F9>=I9,4,IF(F9>=H9,3,IF(F9>=G9,2,1))) -> #N/A
A10: IV. Participatie | B10: 03. Denken/cognitief | C10: Stress op werk of studie | D10: SQ48 | E10: SQ48_WERK_9 | F10: #N/A | G10: 2 | H10: 3 | I10: 4 | J10: =IF(F10>=I10,4,IF(F10>=H10,3,IF(F10>=G10,2,1))) -> #N/A
A11: III. Activiteiten | B11: 04. Sociaal/affiliatief | C11: Onenigheid met anderen | D11: SQ48 | E11: SQ48_VIJAND_10 | F11: #N/A | G11: 2 | H11: 3 | I11: 4 | J11: =IF(F11>=I11,4,IF(F11>=H11,3,IF(F11>=G11,2,1))) -> #N/A
A12: II. Functies/anatomisch | B12: 05. Lichaam/regulatie | C12: Pijn/druk op de borst | D12: SQ48 | E12: SQ48_SOMAT_11 | F12: #N/A | G12: 2 | H12: 3 | I12: 4 | J12: =IF(F12>=I12,4,IF(F12>=H12,3,IF(F12>=G12,2,1))) -> #N/A
A13: III. Activiteiten | B13: 02. Stemming/positief affect | C13: Uitkijken naar dingen | D13: SQ48 | E13: SQ48_VITAL_12 | F13: #N/A | G13: 2 | H13: 3 | I13: 4 | J13: =IF(F13>=I13,4,IF(F13>=H13,3,IF(F13>=G13,2,1))) -> #N/A
... A85: III. Activiteiten | B85: 04. Sociaal/affiliatief | C85: Eentje dingen doen | D85: WHODAS | E85: WHODAS_PARTICIPATIE_68 | F85: #N/A | G85: 2 | H85: 3 | I85: 4 | J85: =IF(F85>=I85,4,IF(F85>=H85,3,IF(F85>=G85,2,1))) -> #N/A
A86: VI. Persoonlijke factoren | B86: 08. Crisis | C86: Gezond en gelukkig | D86: IROC | E86: IROC_1 | F86: #N/A | G86: 2 | H86: 3 | I86: 4 | J86: =IF(F86=3,3,IF(F86=4,2,IF(F86<=2,4,IF(F86>=5,1)))) -> #N/A
A87: III. Activiteiten | B87: 05. Lichaam/regulatie | C87: Vaardigheden voor zelfzorg | D87: IROC | E87: IROC_2 | F87: #N/A | G87: 2 | H87: 3 | I87: 4 | J87: =IF(F87=3,3,IF(F87=4,2,IF(F87<=2,4,IF(F87>=5,1)))) -> #N/A
A88: V. Externe Factoren | B88: 07. Extern | C88: Veilig gevoel in en rond woning | D88: IROC | E88: IROC_3 | F88: #N/A | G88: 2 | H88: 3 | I88: 4 | J88: =IF(F88=3,3,IF(F88=4,2,IF(F88<=2,4,IF(F88>=5,1)))) -> #N/A
A89: III. Activiteiten | B89: 05. Lichaam/regulatie | C89: Lichamelijk gezond | D89: IROC | E89: IROC_4 | F89: #N/A | G89: 2 | H89: 3 | I89: 4 | J89: =IF(F89=3,3,IF(F89=4,2,IF(F89<=2,4,IF(F89>=5,1)))) -> #N/A
A90: III. Activiteiten | B90: 06. Activatie/sensorimotorisch | C90: Lichamelijk actief en lichaamsbeweging | D90: IROC | E90: IROC_5 | F90: #N/A | G90: 2 | H90: 3 | I90: 4 | J90: =IF(F90=3,3,IF(F90=4,2,IF(F90<=2,4,IF(F90>=5,1)))) -> #N/A
A91: VI. Persoonlijke factoren | B91: 09. Zingeving/purpose | C91: Zinvol bezig | D91: IROC | E91: IROC_6 | F91: #N/A | G91: 2 | H91: 3 | I91: 4 | J91: =IF(F91=3,3,IF(F91=4,2,IF(F91<=2,4,IF(F91>=5,1)))) -> #N/A
A92: V. Externe Factoren | B92: 07. Extern | C92: Steun van vrienden/dierbaren | D92: IROC | E92: IROC_7 | F92: #N/A | G92: 2 | H92: 3 | I92: 4 | J92: =IF(F92=3,3,IF(F92=4,2,IF(F92<=2,4,IF(F92>=5,1)))) -> #N/A
A93: IV. Participatie | B93: 04. Sociaal/affiliatief | C93: Deelnemen aan groepsactiviteiten | D93: IROC | E93: IROC_8 | F93: #N/A | G93: 2 | H93: 3 | I93: 4 | J93: =IF(F93=3,3,IF(F93=4,2,IF(F93<=2,4,IF(F93>=5,1)))) -> #N/A
A94: II. Functies/anatomisch | B94: 04. Sociaal/affiliatief | C94: Zelfwaardering | D94: IROC | E94: IROC_9 | F94: #N/A | G94: 2 | H94: 3 | I94: 4 | J94: =IF(F94=3,3,IF(F94=4,2,IF(F94<=2,4,IF(F94>=5,1)))) -> #N/A
A95: IV. Participatie | B95: 04. Sociaal/affiliatief | C95: Zelf beslissen over leven | D95: IROC | E95: IROC_10 | F95: #N/A | G95: 2 | H95: 3 | I95: 4 | J95: =IF(F95=3,3,IF(F95=4,2,IF(F95<=2,4,IF(F95>=5,1)))) -> #N/A
A96: VI. Persoonlijke factoren | B96: 09. Zingeving/purpose | C96: Eigen leven leiden | D96: IROC | E96: IROC_11 | F96: #N/A | G96: 2 | H96: 3 | I96: 4 | J96: =IF(F96=3,3,IF(F96=4,2,IF(F96<=2,4,IF(F96>=5,1)))) -> #N/A
A97: VI. Persoonlijke factoren | B97: 09. Zingeving/purpose | C97: Hoopvol over de toekomst | D97: IROC | E97: IROC_12 | F97: #N/A | G97: 2 | H97: 3 | I97: 4 | J97: =IF(F97=3,3,IF(F97=4,2,IF(F97<=2,4,IF(F97>=5,1)))) -> #N/A
C98: Stemming positief | D98: IROC | E98: IROC_1a | F98: #N/A | G98: 2 | H98: 3 | I98: 4 | J98: =IF(F98=3,3,IF(F98=4,2,IF(F98<=2,4,IF(F98>=5,1)))) -> #N/A
C99: Zorgen gemaakt | D99: IROC | E99: IROC_1b | F99: #N/A | G99: 2 | H99: 3 | I99: 4 | J99: =IF(F99=3,3,IF(F99=4,2,IF(F99<=2,4,IF(F99>=5,1)))) -> #N/A
C100: Gespannen en angstig | D100: IROC | E100: IROC_1c | F100: #N/A | G100: 2 | H100: 3 | I100: 4 | J100: =IF(F100=3,3,IF(F100=4,2,IF(F100<=2,4,IF(F100>=5,1)))) -> #N/A
C101: Concentreren | D101: IROC | E101: IROC_1d | F101: #N/A | G101: 2 | H101: 3 | I101: 4 | J101: =IF(F101=3,3,IF(F101=4,2,IF(F101<=2,4,IF(F101>=5,1)))) -> #N/A
C102: Goed gevoel zelf | D102: IROC | E102: IROC_1e | F102: #N/A | G102: 2 | H102: 3 | I102: 4 | J102: =IF(F102=3,3,IF(F102=4,2,IF(F102<=2,4,IF(F102>=5,1)))) -> #N/A
C103: Iets nieuws proberen | D103: IROC | E103: IROC_1f | F103: #N/A | G103: 2 | H103: 3 | I103: 4 | J103: =IF(F103=3,3,IF(F103=4,2,IF(F103<=2,4,IF(F103>=5,1)))) -> #N/A
C104: Goed geslapen | D104: IROC | E104: IROC_1g | F104: #N/A | G104: 2 | H104: 3 | I104: 4 | J104: =IF(F104=3,3,IF(F104=4,2,IF(F104<=2,4,IF(F104>=5,1)))) -> #N/A
C105: Uit kunnen kijken | D105: IROC | E105: IROC_1h | F105: #N/A | G105: 2 | H105: 3 | I105: 4 | J105: =IF(F105=3,3,IF(F105=4,2,IF(F105<=2,4,IF(F105>=5,1)))) -> #N/A
C106: Voor uzelf zorgen | D106: IROC | E106: IROC_2a | F106: #N/A | G106: 2 | H106: 3 | I106: 4 | J106: =IF(F106=3,3,IF(F106=4,2,IF(F106<=2,4,IF(F106>=5,1)))) -> #N/A
C107: Voor uw huis zorgen | D107: IROC | E107: IROC_2b | F107: #N/A | G107: 2 | H107: 3 | I107: 4 | J107: =IF(F107=3,3,IF(F107=4,2,IF(F107<=2,4,IF(F107>=5,1)))) -> #N/A
C108: Geld budgetteren | D108: IROC | E108: IROC_2c | F108: #N/A | G108: 2 | H108: 3 | I108: 4 | J108: =IF(F108=3,3,IF(F108=4,2,IF(F108<=2,4,IF(F108>=5,1)))) -> #N/A
C109: Rekeningen betalen | D109: IROC | E109: IROC_2d | F109: #N/A | G109: 2 | H109: 3 | I109: 4 | J109: =IF(F109=3,3,IF(F109=4,2,IF(F109<=2,4,IF(F109>=5,1)))) -> #N/A
... C145: Zelf anderen gesteund | D145: IROC | E145: IROC_7e | F145: #N/A | G145: 2 | H145: 3 | I145: 4 | J145: =IF(F145=3,3,IF(F145=4,2,IF(F145<=2,4,IF(F145>=5,1)))) -> #N/A
C146: Tijd alleen doorgebracht | D146: IROC | E146: IROC_8a | F146: #N/A | G146: 2 | H146: 3 | I146: 4 | J146: =IF(F146=3,3,IF(F146=4,2,IF(F146<=2,4,IF(F146>=5,1)))) -> #N/A | K146: Hoe heeft u uw tijd doorgebracht? / Heeft u uw tijd alleen doorgebracht?
...

Sheet Grafiek

Sheet Tabel
A3: Rijlabels | B3: Gemiddelde van ICF score_totaal
A4: II. Functies/anatomisch
A5: 01. Stress/negatief affect
A6: Bang of angstig voelen | B6: 3
A7: Gespannen voelen | B7: 4
A8: Schrikachtig zijn | B8: 4
A9: Zenuwachtig/nerveus zijn | B9: 3
A10: 02. Stemming/positief affect
A11: Hopeloos voelen | B11: 2
A12: Ontevreden zijn | B12: 3
A13: Somber/depressief voelen | B13: 3
A14: 03. Denken/cognitief
A15: 10 minuten concentreren | B15: 3
A16: Concentratieproblemen | B16: 3
A17: Vergeetachtig zijn | B17: 3
A18: 04. Sociaal/affiliatief
A19: Intimiteit ervaren | B19: 4
A20: Minder dan anderen voelen | B20: 3
A21: Neiging te slaan | B21: 1
A22: Ongemakkelijk door anderen | B22: 2
A23: Onzeker in gezelschap | B23: 3
A24: Plannen/zichzelf doelen stellen | B24: 2
A25: Zelfwaardering | B25: 4
A26: 05. Lichaam/regulatie
A27: Hartkloppingen | B27: 3
A28: Kortademig zonder inspanning | B28: 1
A29: Pijn/druk op de borst | B29: 1
A30: Rillerig voelen | B30: 1
A31: Tintelingen bv handen | B31: 1
A32: 06. Activatie/sensorimotorisch
A33: Energiek/levenslustig voelen | B33: 2
A34: Moeite om op gang te komen | B34: 2
A35: Vertraagd of langzaam voelen | B35: 3
A36: III. Activiteiten
A37: 01. Stress/negatief affect
A38: Angstig in menigte zijn | B38: 3
A39: Moeite woedebeheersing | B39: 1
A40: Piekeren | B40: 3
A41: 02. Stemming/positief affect
A42: Interesse in dingen | B42: 2
...

Sheet ICF Bilan
B2: I. (Omgeving) | D2: II. (DSM) | G2: =IFERROR(VLOOKUP(B2,Itemoverzicht!$C:$J,8,FALSE),"xxx") -> xxx | H2: =IFERROR(VLOOKUP(C2,Itemoverzicht!$C:$J,8,FALSE),"xxx") -> xxx | I2: =IFERROR(VLOOKUP(D2,Itemoverzicht!$C:$J,8,FALSE),"xxx") -> xxx
B3: III. Functies/Anatomisch | C3: IV. Activiteiten | D3: V. Participatie | G3: =IFERROR(VLOOKUP(B3,Itemoverzicht!$C:$J,8,FALSE),"xxx") -> xxx | H3: =IFERROR(VLOOKUP(C3,Itemoverzicht!$C:$J,8,FALSE),"xxx") -> xxx | I3: =IFERROR(VLOOKUP(D3,Itemoverzicht!$C:$J,8,FALSE),"xxx") -> xxx
B4: 01. Stress/negatief affect | C4: 01. Stress/negatief affect | D4: 01. Stress/negatief affect | G4: =IFERROR(VLOOKUP(B4,Itemoverzicht!$C:$J,8,FALSE),"xxx") -> xxx | H4: =IFERROR(VLOOKUP(C4,Itemoverzicht!$C:$J,8,FALSE),"xxx") -> xxx | I4: =IFERROR(VLOOKUP(D4,Itemoverzicht!$C:$J,8,FALSE),"xxx") -> xxx
B5: Bang of angstig voelen | C5: Moeite woedebeheersing | D5: Niet alleen openbaar vervoer | G5: =IFERROR(VLOOKUP(B5,Itemoverzicht!$C:$J,8,FALSE),"xxx") -> xxx | H5: =IFERROR(VLOOKUP(C5,Itemoverzicht!$C:$J,8,FALSE),"xxx") -> xxx | I5: =IFERROR(VLOOKUP(D5,Itemoverzicht!$C:$J,8,FALSE),"xxx") -> xxx
B6: Schrikachtig zijn | C6: Piekeren | D6: Zomaar opvliegend zijn | G6: =IFERROR(VLOOKUP(B6,Itemoverzicht!$C:$J,8,FALSE),"xxx") -> xxx | H6: =IFERROR(VLOOKUP(C6,Itemoverzicht!$C:$J,8,FALSE),"xxx") -> xxx | I6: =IFERROR(VLOOKUP(D6,Itemoverzicht!$C:$J,8,FALSE),"xxx") -> xxx
B7: Zenuwachtig/nerveus zijn | C7: Angstig in menigte zijn | D7: Niet alleen naar drukke winkel | G7: =IFERROR(VLOOKUP(B7,Itemoverzicht!$C:$J,8,FALSE),"xxx") -> xxx | H7: =IFERROR(VLOOKUP(C7,Itemoverzicht!$C:$J,8,FALSE),"xxx") -> xxx | I7: =IFERROR(VLOOKUP(D7,Itemoverzicht!$C:$J,8,FALSE),"xxx") -> xxx
B8: Gespannen voelen | D8: Moeite met open ruimtes | G8: =IFERROR(VLOOKUP(B8,Itemoverzicht!$C:$J,8,FALSE),"xxx") -> xxx | H8: =IFERROR(VLOOKUP(C8,Itemoverzicht!$C:$J,8,FALSE),"xxx") -> xxx | I8: =IFERROR(VLOOKUP(D8,Itemoverzicht!$C:$J,8,FALSE),"xxx") -> xxx
B9: 02. Stemming/positief affect | C9: 02. Stemming/positief affect | D9: 02. Stemming/positief affect | G9: =IFERROR(VLOOKUP(B9,Itemoverzicht!$C:$J,8,FALSE),"xxx") -> xxx | H9: =IFERROR(VLOOKUP(C9,Itemoverzicht!$C:$J,8,FALSE),"xxx") -> xxx | I9: =IFERROR(VLOOKUP(D9,Itemoverzicht!$C:$J,8,FALSE),"xxx") -> xxx
B10: Hopeloos voelen | C10: Uitkijken naar dingen | D10: Geen voldoening van werk | G10: =IFERROR(VLOOKUP(B10,Itemoverzicht!$C:$J,8,FALSE),"xxx") -> xxx | H10: =IFERROR(VLOOKUP(C10,Itemoverzicht!$C:$J,8,FALSE),"xxx") -> xxx | I10: =IFERROR(VLOOKUP(D10,Itemoverzicht!$C:$J,8,FALSE),"xxx") -> xxx
B11: Somber/depressief voelen | C11: Interesse in dingen | D11: Zin om dingen te doen | G11: =IFERROR(VLOOKUP(B11,Itemoverzicht!$C:$J,8,FALSE),"xxx") -> xxx | H11: =IFERROR(VLOOKUP(C11,Itemoverzicht!$C:$J,8,FALSE),"xxx") -> xxx | I11: =IFERROR(VLOOKUP(D11,Itemoverzicht!$C:$J,8,FALSE),"xxx") -> xxx
B12: Ontevreden zijn | C12: Niet kunnen genieten | D12: Moeite met beslissingen | G12: =IFERROR(VLOOKUP(B12,Itemoverzicht!$C:$J,8,FALSE),"xxx") -> xxx | H12: =IFERROR(VLOOKUP(C12,Itemoverzicht!$C:$J,8,FALSE),"xxx") -> xxx | I12: =IFERROR(VLOOKUP(D12,Itemoverzicht!$C:$J,8,FALSE),"xxx") -> xxx
B13: 03. Denken/cognitief | C13: 03. Denken/cognitief | D13: 03. Denken/cognitief | G13: =IFERROR(VLOOKUP(B13,Itemoverzicht!$C:$J,8,FALSE),"xxx") -> xxx | H13: =IFERROR(VLOOKUP(C13,Itemoverzicht!$C:$J,8,FALSE),"xxx") -> xxx | I13: =IFERROR(VLOOKUP(D13,Itemoverzicht!$C:$J,8,FALSE),"xxx") -> xxx
B14: Vergeetachtig zijn | C14: Huishouden op goede manier | D14: Begrijpen wat mensen zeggen | G14: =IFERROR(VLOOKUP(B14,Itemoverzicht!$C:$J,8,FALSE),"xxx") -> xxx | H14: =IFERROR(VLOOKUP(C14,Itemoverzicht!$C:$J,8,FALSE),"xxx") -> xxx | I14: =IFERROR(VLOOKUP(D14,Itemoverzicht!$C:$J,8,FALSE),"xxx") -> xxx
B15: Concentratieproblemen | C15: Nieuwe taak leren | D15: Huishoudelijke verantwoordelijkheid | G15: =IFERROR(VLOOKUP(B15,Itemoverzicht!$C:$J,8,FALSE),"xxx") -> xxx | H15: =IFERROR(VLOOKUP(C15,Itemoverzicht!$C:$J,8,FALSE),"xxx") -> xxx | I15: =IFERROR(VLOOKUP(D15,Itemoverzicht!$C:$J,8,FALSE),"xxx") -> xxx
B16: 10 minuten concentreren | C16: Onthouden van belangrijke dingen | D16: Oplossingen in dagelijks leven | G16: =IFERROR(VLOOKUP(B16,Itemoverzicht!$C:$J,8,FALSE),"xxx") -> xxx | H16: =IFERROR(VLOOKUP(C16,Itemoverzicht!$C:$J,8,FALSE),"xxx") -> xxx | I16: =IFERROR(VLOOKUP(D16,Itemoverzicht!$C:$J,8,FALSE),"xxx") -> xxx
C17: Stress op werk of studie | D17: Werk/studieproblemen | G17: =IFERROR(VLOOKUP(B17,Itemoverzicht!$C:$J,8,FALSE),"xxx") -> xxx | H17: =IFERROR(VLOOKUP(C17,Itemoverzicht!$C:$J,8,FALSE),"xxx") -> xxx | I17: =IFERROR(VLOOKUP(D17,Itemoverzicht!$C:$J,8,FALSE),"xxx") -> xxx
C18: Werk/school op goede manier | D18: Dagelijkse werk/school | G18: =IFERROR(VLOOKUP(B18,Itemoverzicht!$C:$J,8,FALSE),"xxx") -> xxx | H18: =IFERROR(VLOOKUP(C18,Itemoverzicht!$C:$J,8,FALSE),"xxx") -> xxx | I18: =IFERROR(VLOOKUP(D18,Itemoverzicht!$C:$J,8,FALSE),"xxx") -> xxx
C19: Zelf aankleden | G19: =IFERROR(VLOOKUP(B19,Itemoverzicht!$C:$J,8,FALSE),"xxx") -> xxx | H19: =IFERROR(VLOOKUP(C19,Itemoverzicht!$C:$J,8,FALSE),"xxx") -> xxx | I19: =IFERROR(VLOOKUP(D19,Itemoverzicht!$C:$J,8,FALSE),"xxx") -> xxx
B20: 04. Sociaal/affiliatief | C20: 04. Sociaal/affiliatief | D20: 04. Sociaal/affiliatief | G20: =IFERROR(VLOOKUP(B20,Itemoverzicht!$C:$J,8,FALSE),"xxx") -> xxx | H20: =IFERROR(VLOOKUP(C20,Itemoverzicht!$C:$J,8,FALSE),"xxx") -> xxx | I20: =IFERROR(VLOOKUP(D20,Itemoverzicht!$C:$J,8,FALSE),"xxx") -> xxx
B21: Intimiteit ervaren | C21: Alleen zijn enkele dagen | D21: Deelnemen aan groepsactiviteiten | G21: =IFERROR(VLOOKUP(B21,Itemoverzicht!$C:$J,8,FALSE),"xxx") -> xxx | H21: =IFERROR(VLOOKUP(C21,Itemoverzicht!$C:$J,8,FALSE),"xxx") -> xxx | I21: =IFERROR(VLOOKUP(D21,Itemoverzicht!$C:$J,8,FALSE),"xxx") -> xxx
B22: Minder dan anderen voelen | C22: Eentje dingen doen | D22: Moeite gemeenschapsactiviteit | G22: =IFERROR(VLOOKUP(B22,Itemoverzicht!$C:$J,8,FALSE),"xxx") -> xxx | H22: =IFERROR(VLOOKUP(C22,Itemoverzicht!$C:$J,8,FALSE),"xxx") -> xxx | I22: =IFERROR(VLOOKUP(D22,Itemoverzicht!$C:$J,8,FALSE),"xxx") -> xxx
B23: Zelfwaardering | C23: Gesprek gaande houden | D23: Nieuwe vrienden maken | G23: =IFERROR(VLOOKUP(B23,Itemoverzicht!$C:$J,8,FALSE),"xxx") -> xxx | H23: =IFERROR(VLOOKUP(C23,Itemoverzicht!$C:$J,8,FALSE),"xxx") -> xxx | I23: =IFERROR(VLOOKUP(D23,Itemoverzicht!$C:$J,8,FALSE),"xxx") -> xxx
B24: Plannen/zichzelf doelen stellen | C24: Omgaan met onbekenden | D24: Onderhouden vriendschap | G24: =IFERROR(VLOOKUP(B24,Itemoverzicht!$C:$J,8,FALSE),"xxx") -> xxx | H24: =IFERROR(VLOOKUP(C24,Itemoverzicht!$C:$J,8,FALSE),"xxx") -> xxx | I24: =IFERROR(VLOOKUP(D24,Itemoverzicht!$C:$J,8,FALSE),"xxx") -> xxx
B25: Ongemakkelijk door anderen | C25: Onenigheid met anderen | D25: Seksuele activiteit | G25: =IFERROR(VLOOKUP(B25,Itemoverzicht!$C:$J,8,FALSE),"xxx") -> xxx | H25: =IFERROR(VLOOKUP(C25,Itemoverzicht!$C:$J,8,FALSE),"xxx") -> xxx | I25: =IFERROR(VLOOKUP(D25,Itemoverzicht!$C:$J,8,FALSE),"xxx") -> xxx
B26: Neiging te slaan | C26: Bang voor afwijzing in groep | D26: Zelf beslissen over leven | G26: =IFERROR(VLOOKUP(B26,Itemoverzicht!$C:$J,8,FALSE),"xxx") -> xxx | H26: =IFERROR(VLOOKUP(C26,Itemoverzicht!$C:$J,8,FALSE),"xxx") -> xxx | I26: =IFERROR(VLOOKUP(D26,Itemoverzicht!$C:$J,8,FALSE),"xxx") -> xxx
B27: Onzeker in gezelschap | C27: Moeilijk mening uiten | G27: =IFERROR(VLOOKUP(B27,Itemoverzicht!$C:$J,8,FALSE),"xxx") -> xxx | H27: =IFERROR(VLOOKUP(C27,Itemoverzicht!$C:$J,8,FALSE),"xxx") -> xxx | I27: =IFERROR(VLOOKUP(D27,Itemoverzicht!$C:$J,8,FALSE),"xxx") -> xxx
B28: 05. Lichaam/regulatie | C28: 05. Lichaam/regulatie | D28: 05. Lichaam/regulatie | G28: =IFERROR(VLOOKUP(B28,Itemoverzicht!$C:$J,8,FALSE),"xxx") -> xxx | H28: =IFERROR(VLOOKUP(C28,Itemoverzicht!$C:$J,8,FALSE),"xxx") -> xxx | I28: =IFERROR(VLOOKUP(D28,Itemoverzicht!$C:$J,8,FALSE),"xxx") -> xxx
B29: Kortademig zonder inspanning | C29: Lichamelijk gezond | D29: Moeite met eten | G29: =IFERROR(VLOOKUP(B29,Itemoverzicht!$C:$J,8,FALSE),"xxx") -> xxx | H29: =IFERROR(VLOOKUP(C29,Itemoverzicht!$C:$J,8,FALSE),"xxx") -> xxx | I29: =IFERROR(VLOOKUP(D29,Itemoverzicht!$C:$J,8,FALSE),"xxx") -> xxx
B30: Tintelingen bv handen | C30: Onrustig voelen | D30: Trilde of beefde | G30: =IFERROR(VLOOKUP(B30,Itemoverzicht!$C:$J,8,FALSE),"xxx") -> xxx | H30: =IFERROR(VLOOKUP(C30,Itemoverzicht!$C:$J,8,FALSE),"xxx") -> xxx | I30: =IFERROR(VLOOKUP(D30,Itemoverzicht!$C:$J,8,FALSE),"xxx") -> xxx
B31: Hartkloppingen | C31: Vaardigheden voor zelfzorg | D31: Wassen van hele lichaam | G31: =IFERROR(VLOOKUP(B31,Itemoverzicht!$C:$J,8,FALSE),"xxx") -> xxx | H31: =IFERROR(VLOOKUP(C31,Itemoverzicht!$C:$J,8,FALSE),"xxx") -> xxx | I31: =IFERROR(VLOOKUP(D31,Itemoverzicht!$C:$J,8,FALSE),"xxx") -> xxx
B32: Rillerig voelen | C32: Duizelig voelen | G32: =IFERROR(VLOOKUP(B32,Itemoverzicht!$C:$J,8,FALSE),"xxx") -> xxx | H32: =IFERROR(VLOOKUP(C32,Itemoverzicht!$C:$J,8,FALSE),"xxx") -> xxx | I32: =IFERROR(VLOOKUP(D32,Itemoverzicht!$C:$J,8,FALSE),"xxx") -> xxx
B33: Pijn/druk op de borst | G33: =IFERROR(VLOOKUP(B33,Itemoverzicht!$C:$J,8,FALSE),"xxx") -> xxx | H33: =IFERROR(VLOOKUP(C33,Itemoverzicht!$C:$J,8,FALSE),"xxx") -> xxx | I33: =IFERROR(VLOOKUP(D33,Itemoverzicht!$C:$J,8,FALSE),"xxx") -> xxx
B34: 06. Activatie/sensorimotorisch | C34: 06. Activatie/sensorimotorisch | D34: 06. Activatie/sensorimotorisch | G34: =IFERROR(VLOOKUP(B34,Itemoverzicht!$C:$J,8,FALSE),"xxx") -> xxx | H34: =IFERROR(VLOOKUP(C34,Itemoverzicht!$C:$J,8,FALSE),"xxx") -> xxx | I34: =IFERROR(VLOOKUP(D34,Itemoverzicht!$C:$J,8,FALSE),"xxx") -> xxx
B35: Vertraagd of langzaam voelen | C35: Huishouden zo snel als nodig | D35: Huishouden afkrijgen | G35: =IFERROR(VLOOKUP(B35,Itemoverzicht!$C:$J,8,FALSE),"xxx") -> xxx | H35: =IFERROR(VLOOKUP(C35,Itemoverzicht!$C:$J,8,FALSE),"xxx") -> xxx | I35: =IFERROR(VLOOKUP(D35,Itemoverzicht!$C:$J,8,FALSE),"xxx") -> xxx
B36: Energiek/levenslustig voelen | C36: Lange afstand lopen | D36: Uit huis komen | G36: =IFERROR(VLOOKUP(B36,Itemoverzicht!$C:$J,8,FALSE),"xxx") -> xxx | H36: =IFERROR(VLOOKUP(C36,Itemoverzicht!$C:$J,8,FALSE),"xxx") -> xxx | I36: =IFERROR(VLOOKUP(D36,Itemoverzicht!$C:$J,8,FALSE),"xxx") -> xxx
B37: Moeite om op gang te komen | C37: Lichamelijk actief en lichaamsbeweging | D37: Gevoel teveel te werken | G37: =IFERROR(VLOOKUP(B37,Itemoverzicht!$C:$J,8,FALSE),"xxx") -> xxx | H37: =IFERROR(VLOOKUP(C37,Itemoverzicht!$C:$J,8,FALSE),"xxx") -> xxx | I37: =IFERROR(VLOOKUP(D37,Itemoverzicht!$C:$J,8,FALSE),"xxx") -> xxx
C38: Meer dan 30 min staan | D38: Minder hard werken/studeren | G38: =IFERROR(VLOOKUP(B38,Itemoverzicht!$C:$J,8,FALSE),"xxx") -> xxx | H38: =IFERROR(VLOOKUP(C38,Itemoverzicht!$C:$J,8,FALSE),"xxx") -> xxx | I38: =IFERROR(VLOOKUP(D38,Itemoverzicht!$C:$J,8,FALSE),"xxx") -> xxx
C39: Opstaan uit zit | D39: Werk/school afkrijgen | G39: =IFERROR(VLOOKUP(B39,Itemoverzicht!$C:$J,8,FALSE),"xxx") -> xxx | H39: =IFERROR(VLOOKUP(C39,Itemoverzicht!$C:$J,8,FALSE),"xxx") -> xxx | I39: =IFERROR(VLOOKUP(D39,Itemoverzicht!$C:$J,8,FALSE),"xxx") -> xxx
C40: Werk/school zo snel als nodig | H40: =IFERROR(VLOOKUP(C40,Itemoverzicht!$C:$J,8,FALSE),"xxx") -> xxx
C41: Verplaatsen in woning | G41: =IFERROR(VLOOKUP(B41,Itemoverzicht!$C:$J,8,FALSE),"xxx") -> xxx | H41: =IFERROR(VLOOKUP(C41,Itemoverzicht!$C:$J,8,FALSE),"xxx") -> xxx | I41: =IFERROR(VLOOKUP(D41,Itemoverzicht!$C:$J,8,FALSE),"xxx") -> xxx
...
